I'm sorry, but an uncaught exception occurred.

While running game code:
  File "game/script.rpy", line 263, in script
    shelby "Продолжение следует..."
Exception: Sayer 'shelby' is not defined.

-- Full Traceback ------------------------------------------------------------

Full traceback:
  File "game/script.rpy", line 263, in script
    shelby "Продолжение следует..."
  File "C:\Novels\renpy\ast.py", line 881, in execute
    who = eval_who(self.who, self.who_fast)
  File "C:\Novels\renpy\ast.py", line 774, in eval_who
    raise Exception("Sayer '%s' is not defined." % who)
Exception: Sayer 'shelby' is not defined.

Windows-10-10.0.19045 AMD64
Ren'Py 8.0.3.22090809
Детективные изыскания Олега Евгеньевича 1.0
Thu Dec 29 20:52:08 2022
